[2023-01-21T06:00:05.481+0000] {taskinstance.py:1083} INFO - Dependencies all met for <TaskInstance: crypto_coins_etl.insert_coins manual__2023-01-21T05:59:59.252678+00:00 [queued]>
[2023-01-21T06:00:05.495+0000] {taskinstance.py:1083} INFO - Dependencies all met for <TaskInstance: crypto_coins_etl.insert_coins manual__2023-01-21T05:59:59.252678+00:00 [queued]>
[2023-01-21T06:00:05.496+0000] {taskinstance.py:1279} INFO - 
--------------------------------------------------------------------------------
[2023-01-21T06:00:05.497+0000] {taskinstance.py:1280} INFO - Starting attempt 1 of 1
[2023-01-21T06:00:05.498+0000] {taskinstance.py:1281} INFO - 
--------------------------------------------------------------------------------
[2023-01-21T06:00:05.513+0000] {taskinstance.py:1300} INFO - Executing <Task(PythonOperator): insert_coins> on 2023-01-21 05:59:59.252678+00:00
[2023-01-21T06:00:05.523+0000] {standard_task_runner.py:55} INFO - Started process 2573 to run task
[2023-01-21T06:00:05.527+0000] {standard_task_runner.py:82} INFO - Running: ['***', 'tasks', 'run', 'crypto_coins_etl', 'insert_coins', 'manual__2023-01-21T05:59:59.252678+00:00', '--job-id', '58', '--raw', '--subdir', 'DAGS_FOLDER/crypto_coins_etl.py', '--cfg-path', '/tmp/tmp3wmvuzbu']
[2023-01-21T06:00:05.531+0000] {standard_task_runner.py:83} INFO - Job 58: Subtask insert_coins
[2023-01-21T06:00:05.611+0000] {task_command.py:388} INFO - Running <TaskInstance: crypto_coins_etl.insert_coins manual__2023-01-21T05:59:59.252678+00:00 [running]> on host ac5a85f5e1cc
[2023-01-21T06:00:05.695+0000] {taskinstance.py:1507} INFO - Exporting the following env vars:
AIRFLOW_CTX_DAG_OWNER=***
AIRFLOW_CTX_DAG_ID=crypto_coins_etl
AIRFLOW_CTX_TASK_ID=insert_coins
AIRFLOW_CTX_EXECUTION_DATE=2023-01-21T05:59:59.252678+00:00
AIRFLOW_CTX_TRY_NUMBER=1
AIRFLOW_CTX_DAG_RUN_ID=manual__2023-01-21T05:59:59.252678+00:00
[2023-01-21T06:00:05.730+0000] {taskinstance.py:1768} ERROR - Task failed with exception
Traceback (most recent call last):
  File "/home/airflow/.local/lib/python3.8/site-packages/sqlalchemy/engine/base.py", line 1900, in _execute_context
    self.dialect.do_execute(
  File "/home/airflow/.local/lib/python3.8/site-packages/sqlalchemy/engine/default.py", line 736, in do_execute
    cursor.execute(statement, parameters)
psycopg2.errors.UndefinedTable: relation "coin" does not exist
LINE 2: FROM coin 
             ^


The above exception was the direct cause of the following exception:

Traceback (most recent call last):
  File "/home/airflow/.local/lib/python3.8/site-packages/airflow/operators/python.py", line 175, in execute
    return_value = self.execute_callable()
  File "/home/airflow/.local/lib/python3.8/site-packages/airflow/operators/python.py", line 192, in execute_callable
    return self.python_callable(*self.op_args, **self.op_kwargs)
  File "/opt/airflow/plugins/transformers/crypto/crypto_transformer.py", line 24, in insert_coin_in_db
    Coin.create(coin)
  File "/opt/airflow/plugins/models/coin.py", line 28, in create
    coin_checker = cls.get_coin_by_symbol(coin_info['symbol'])
  File "/opt/airflow/plugins/models/coin.py", line 54, in get_coin_by_symbol
    return cls.query.filter(cls.symbol == symbol).first()
  File "/home/airflow/.local/lib/python3.8/site-packages/sqlalchemy/orm/query.py", line 2824, in first
    return self.limit(1)._iter().first()
  File "/home/airflow/.local/lib/python3.8/site-packages/sqlalchemy/orm/query.py", line 2916, in _iter
    result = self.session.execute(
  File "/home/airflow/.local/lib/python3.8/site-packages/sqlalchemy/orm/session.py", line 1714, in execute
    result = conn._execute_20(statement, params or {}, execution_options)
  File "/home/airflow/.local/lib/python3.8/site-packages/sqlalchemy/engine/base.py", line 1705, in _execute_20
    return meth(self, args_10style, kwargs_10style, execution_options)
  File "/home/airflow/.local/lib/python3.8/site-packages/sqlalchemy/sql/elements.py", line 334, in _execute_on_connection
    return connection._execute_clauseelement(
  File "/home/airflow/.local/lib/python3.8/site-packages/sqlalchemy/engine/base.py", line 1572, in _execute_clauseelement
    ret = self._execute_context(
  File "/home/airflow/.local/lib/python3.8/site-packages/sqlalchemy/engine/base.py", line 1943, in _execute_context
    self._handle_dbapi_exception(
  File "/home/airflow/.local/lib/python3.8/site-packages/sqlalchemy/engine/base.py", line 2124, in _handle_dbapi_exception
    util.raise_(
  File "/home/airflow/.local/lib/python3.8/site-packages/sqlalchemy/util/compat.py", line 211, in raise_
    raise exception
  File "/home/airflow/.local/lib/python3.8/site-packages/sqlalchemy/engine/base.py", line 1900, in _execute_context
    self.dialect.do_execute(
  File "/home/airflow/.local/lib/python3.8/site-packages/sqlalchemy/engine/default.py", line 736, in do_execute
    cursor.execute(statement, parameters)
sqlalchemy.exc.ProgrammingError: (psycopg2.errors.UndefinedTable) relation "coin" does not exist
LINE 2: FROM coin 
             ^

[SQL: SELECT coin.id AS coin_id, coin.name AS coin_name, coin.symbol AS coin_symbol, coin.current_price AS coin_current_price, coin.high_24h AS coin_high_24h, coin.low_24h AS coin_low_24h 
FROM coin 
WHERE coin.symbol = %(symbol_1)s 
 LIMIT %(param_1)s]
[parameters: {'symbol_1': 'btc', 'param_1': 1}]
(Background on this error at: https://sqlalche.me/e/14/f405)
[2023-01-21T06:00:05.758+0000] {taskinstance.py:1318} INFO - Marking task as FAILED. dag_id=crypto_coins_etl, task_id=insert_coins, execution_date=20230121T055959, start_date=20230121T060005, end_date=20230121T060005
[2023-01-21T06:00:05.773+0000] {standard_task_runner.py:100} ERROR - Failed to execute job 58 for task insert_coins ((psycopg2.errors.UndefinedTable) relation "coin" does not exist
LINE 2: FROM coin 
             ^

[SQL: SELECT coin.id AS coin_id, coin.name AS coin_name, coin.symbol AS coin_symbol, coin.current_price AS coin_current_price, coin.high_24h AS coin_high_24h, coin.low_24h AS coin_low_24h 
FROM coin 
WHERE coin.symbol = %(symbol_1)s 
 LIMIT %(param_1)s]
[parameters: {'symbol_1': 'btc', 'param_1': 1}]
(Background on this error at: https://sqlalche.me/e/14/f405); 2573)
[2023-01-21T06:00:05.821+0000] {local_task_job.py:208} INFO - Task exited with return code 1
[2023-01-21T06:00:05.843+0000] {taskinstance.py:2578} INFO - 0 downstream tasks scheduled from follow-on schedule check
