[2023-01-22T04:23:20.354+0000] {taskinstance.py:1083} INFO - Dependencies all met for <TaskInstance: debts_tracker_etl.upload_file_to_vendor_s3_location manual__2023-01-22T04:23:04.602945+00:00 [queued]>
[2023-01-22T04:23:20.365+0000] {taskinstance.py:1083} INFO - Dependencies all met for <TaskInstance: debts_tracker_etl.upload_file_to_vendor_s3_location manual__2023-01-22T04:23:04.602945+00:00 [queued]>
[2023-01-22T04:23:20.366+0000] {taskinstance.py:1279} INFO - 
--------------------------------------------------------------------------------
[2023-01-22T04:23:20.367+0000] {taskinstance.py:1280} INFO - Starting attempt 2 of 2
[2023-01-22T04:23:20.367+0000] {taskinstance.py:1281} INFO - 
--------------------------------------------------------------------------------
[2023-01-22T04:23:20.380+0000] {taskinstance.py:1300} INFO - Executing <Task(PythonOperator): upload_file_to_vendor_s3_location> on 2023-01-22 04:23:04.602945+00:00
[2023-01-22T04:23:20.387+0000] {standard_task_runner.py:55} INFO - Started process 3956 to run task
[2023-01-22T04:23:20.392+0000] {standard_task_runner.py:82} INFO - Running: ['***', 'tasks', 'run', 'debts_tracker_etl', 'upload_file_to_vendor_s3_location', 'manual__2023-01-22T04:23:04.602945+00:00', '--job-id', '73', '--raw', '--subdir', 'DAGS_FOLDER/debts_tracker_etl.py', '--cfg-path', '/tmp/tmp3qfogeqy']
[2023-01-22T04:23:20.398+0000] {standard_task_runner.py:83} INFO - Job 73: Subtask upload_file_to_vendor_s3_location
[2023-01-22T04:23:20.475+0000] {task_command.py:388} INFO - Running <TaskInstance: debts_tracker_etl.upload_file_to_vendor_s3_location manual__2023-01-22T04:23:04.602945+00:00 [running]> on host 4b1c480b6ccb
[2023-01-22T04:23:20.545+0000] {taskinstance.py:1507} INFO - Exporting the following env vars:
AIRFLOW_CTX_DAG_OWNER=Tony Stark, Peter Parker
AIRFLOW_CTX_DAG_ID=debts_tracker_etl
AIRFLOW_CTX_TASK_ID=upload_file_to_vendor_s3_location
AIRFLOW_CTX_EXECUTION_DATE=2023-01-22T04:23:04.602945+00:00
AIRFLOW_CTX_TRY_NUMBER=2
AIRFLOW_CTX_DAG_RUN_ID=manual__2023-01-22T04:23:04.602945+00:00
[2023-01-22T04:23:20.558+0000] {base.py:73} INFO - Using connection ID 'aws_conn' for task execution.
[2023-01-22T04:23:20.560+0000] {connection_wrapper.py:334} INFO - AWS Connection (conn_id='aws_conn', conn_type='aws') credentials retrieved from login and password.
[2023-01-22T04:23:21.397+0000] {taskinstance.py:1768} ERROR - Task failed with exception
Traceback (most recent call last):
  File "/home/airflow/.local/lib/python3.8/site-packages/airflow/operators/python.py", line 175, in execute
    return_value = self.execute_callable()
  File "/home/airflow/.local/lib/python3.8/site-packages/airflow/operators/python.py", line 192, in execute_callable
    return self.python_callable(*self.op_args, **self.op_kwargs)
  File "/opt/airflow/plugins/transformers/debts_tracker/debts_tracker_transformer.py", line 135, in upload_file_to_vendor_s3_folder
    s3_hook.load_file(
  File "/home/airflow/.local/lib/python3.8/site-packages/airflow/providers/amazon/aws/hooks/s3.py", line 99, in wrapper
    return func(*bound_args.args, **bound_args.kwargs)
  File "/home/airflow/.local/lib/python3.8/site-packages/airflow/providers/amazon/aws/hooks/s3.py", line 70, in wrapper
    return func(*bound_args.args, **bound_args.kwargs)
  File "/home/airflow/.local/lib/python3.8/site-packages/airflow/providers/amazon/aws/hooks/s3.py", line 646, in load_file
    client.upload_file(filename, bucket_name, key, ExtraArgs=extra_args, Config=self.transfer_config)
  File "/home/airflow/.local/lib/python3.8/site-packages/boto3/s3/inject.py", line 143, in upload_file
    return transfer.upload_file(
  File "/home/airflow/.local/lib/python3.8/site-packages/boto3/s3/transfer.py", line 292, in upload_file
    future.result()
  File "/home/airflow/.local/lib/python3.8/site-packages/s3transfer/futures.py", line 103, in result
    return self._coordinator.result()
  File "/home/airflow/.local/lib/python3.8/site-packages/s3transfer/futures.py", line 266, in result
    raise self._exception
  File "/home/airflow/.local/lib/python3.8/site-packages/s3transfer/tasks.py", line 269, in _main
    self._submit(transfer_future=transfer_future, **kwargs)
  File "/home/airflow/.local/lib/python3.8/site-packages/s3transfer/upload.py", line 585, in _submit
    upload_input_manager.provide_transfer_size(transfer_future)
  File "/home/airflow/.local/lib/python3.8/site-packages/s3transfer/upload.py", line 244, in provide_transfer_size
    self._osutil.get_file_size(transfer_future.meta.call_args.fileobj)
  File "/home/airflow/.local/lib/python3.8/site-packages/s3transfer/utils.py", line 247, in get_file_size
    return os.path.getsize(filename)
  File "/usr/local/lib/python3.8/genericpath.py", line 50, in getsize
    return os.stat(filename).st_size
FileNotFoundError: [Errno 2] No such file or directory: 'encrypt_debts_file.csv'
[2023-01-22T04:23:21.408+0000] {taskinstance.py:1318} INFO - Marking task as FAILED. dag_id=debts_tracker_etl, task_id=upload_file_to_vendor_s3_location, execution_date=20230122T042304, start_date=20230122T042320, end_date=20230122T042321
[2023-01-22T04:23:21.420+0000] {standard_task_runner.py:100} ERROR - Failed to execute job 73 for task upload_file_to_vendor_s3_location ([Errno 2] No such file or directory: 'encrypt_debts_file.csv'; 3956)
[2023-01-22T04:23:21.451+0000] {local_task_job.py:208} INFO - Task exited with return code 1
[2023-01-22T04:23:21.473+0000] {taskinstance.py:2578} INFO - 0 downstream tasks scheduled from follow-on schedule check
