[2023-01-22T03:32:23.003+0000] {taskinstance.py:1083} INFO - Dependencies all met for <TaskInstance: debts_tracker_etl.create_encrypt_file manual__2023-01-22T03:32:11.891303+00:00 [queued]>
[2023-01-22T03:32:23.014+0000] {taskinstance.py:1083} INFO - Dependencies all met for <TaskInstance: debts_tracker_etl.create_encrypt_file manual__2023-01-22T03:32:11.891303+00:00 [queued]>
[2023-01-22T03:32:23.015+0000] {taskinstance.py:1279} INFO - 
--------------------------------------------------------------------------------
[2023-01-22T03:32:23.016+0000] {taskinstance.py:1280} INFO - Starting attempt 2 of 2
[2023-01-22T03:32:23.017+0000] {taskinstance.py:1281} INFO - 
--------------------------------------------------------------------------------
[2023-01-22T03:32:23.030+0000] {taskinstance.py:1300} INFO - Executing <Task(PythonOperator): create_encrypt_file> on 2023-01-22 03:32:11.891303+00:00
[2023-01-22T03:32:23.036+0000] {standard_task_runner.py:55} INFO - Started process 635 to run task
[2023-01-22T03:32:23.041+0000] {standard_task_runner.py:82} INFO - Running: ['***', 'tasks', 'run', 'debts_tracker_etl', 'create_encrypt_file', 'manual__2023-01-22T03:32:11.891303+00:00', '--job-id', '27', '--raw', '--subdir', 'DAGS_FOLDER/debts_tracker_etl.py', '--cfg-path', '/tmp/tmpsra0wtjg']
[2023-01-22T03:32:23.045+0000] {standard_task_runner.py:83} INFO - Job 27: Subtask create_encrypt_file
[2023-01-22T03:32:23.123+0000] {task_command.py:388} INFO - Running <TaskInstance: debts_tracker_etl.create_encrypt_file manual__2023-01-22T03:32:11.891303+00:00 [running]> on host 4b1c480b6ccb
[2023-01-22T03:32:23.192+0000] {taskinstance.py:1507} INFO - Exporting the following env vars:
AIRFLOW_CTX_DAG_OWNER=Tony Stark, Peter Parker
AIRFLOW_CTX_DAG_ID=debts_tracker_etl
AIRFLOW_CTX_TASK_ID=create_encrypt_file
AIRFLOW_CTX_EXECUTION_DATE=2023-01-22T03:32:11.891303+00:00
AIRFLOW_CTX_TRY_NUMBER=2
AIRFLOW_CTX_DAG_RUN_ID=manual__2023-01-22T03:32:11.891303+00:00
[2023-01-22T03:32:23.213+0000] {taskinstance.py:1768} ERROR - Task failed with exception
Traceback (most recent call last):
  File "/home/airflow/.local/lib/python3.8/site-packages/airflow/operators/python.py", line 175, in execute
    return_value = self.execute_callable()
  File "/home/airflow/.local/lib/python3.8/site-packages/airflow/operators/python.py", line 192, in execute_callable
    return self.python_callable(*self.op_args, **self.op_kwargs)
  File "/opt/airflow/plugins/transformers/debts_tracker/debts_tracker_transformer.py", line 118, in encrypt_debts_data
    with open(f'/opt/airflow/encryted_files/{today_date}/encrypt_debts_file.csv', 'wb') as encrypted_file:
FileNotFoundError: [Errno 2] No such file or directory: '/opt/airflow/encryted_files/2023-01-22_03-32-23/encrypt_debts_file.csv'
[2023-01-22T03:32:23.224+0000] {taskinstance.py:1318} INFO - Marking task as FAILED. dag_id=debts_tracker_etl, task_id=create_encrypt_file, execution_date=20230122T033211, start_date=20230122T033223, end_date=20230122T033223
[2023-01-22T03:32:23.235+0000] {standard_task_runner.py:100} ERROR - Failed to execute job 27 for task create_encrypt_file ([Errno 2] No such file or directory: '/opt/airflow/encryted_files/2023-01-22_03-32-23/encrypt_debts_file.csv'; 635)
[2023-01-22T03:32:23.254+0000] {local_task_job.py:208} INFO - Task exited with return code 1
[2023-01-22T03:32:23.277+0000] {taskinstance.py:2578} INFO - 0 downstream tasks scheduled from follow-on schedule check
