[2023-01-22T01:44:58.114+0000] {taskinstance.py:1083} INFO - Dependencies all met for <TaskInstance: debts_tracker_etl.validate_payment_data manual__2023-01-22T01:44:53.246900+00:00 [queued]>
[2023-01-22T01:44:58.127+0000] {taskinstance.py:1083} INFO - Dependencies all met for <TaskInstance: debts_tracker_etl.validate_payment_data manual__2023-01-22T01:44:53.246900+00:00 [queued]>
[2023-01-22T01:44:58.128+0000] {taskinstance.py:1279} INFO - 
--------------------------------------------------------------------------------
[2023-01-22T01:44:58.128+0000] {taskinstance.py:1280} INFO - Starting attempt 1 of 2
[2023-01-22T01:44:58.129+0000] {taskinstance.py:1281} INFO - 
--------------------------------------------------------------------------------
[2023-01-22T01:44:58.143+0000] {taskinstance.py:1300} INFO - Executing <Task(PythonOperator): validate_payment_data> on 2023-01-22 01:44:53.246900+00:00
[2023-01-22T01:44:58.149+0000] {standard_task_runner.py:55} INFO - Started process 16955 to run task
[2023-01-22T01:44:58.154+0000] {standard_task_runner.py:82} INFO - Running: ['***', 'tasks', 'run', 'debts_tracker_etl', 'validate_payment_data', 'manual__2023-01-22T01:44:53.246900+00:00', '--job-id', '266', '--raw', '--subdir', 'DAGS_FOLDER/debts_tracker_etl.py', '--cfg-path', '/tmp/tmpmbylv8tt']
[2023-01-22T01:44:58.158+0000] {standard_task_runner.py:83} INFO - Job 266: Subtask validate_payment_data
[2023-01-22T01:44:58.238+0000] {task_command.py:388} INFO - Running <TaskInstance: debts_tracker_etl.validate_payment_data manual__2023-01-22T01:44:53.246900+00:00 [running]> on host 365d47c8e5b5
[2023-01-22T01:44:58.312+0000] {taskinstance.py:1507} INFO - Exporting the following env vars:
AIRFLOW_CTX_DAG_OWNER=Tony Stark, Peter Parker
AIRFLOW_CTX_DAG_ID=debts_tracker_etl
AIRFLOW_CTX_TASK_ID=validate_payment_data
AIRFLOW_CTX_EXECUTION_DATE=2023-01-22T01:44:53.246900+00:00
AIRFLOW_CTX_TRY_NUMBER=1
AIRFLOW_CTX_DAG_RUN_ID=manual__2023-01-22T01:44:53.246900+00:00
[2023-01-22T01:44:58.327+0000] {taskinstance.py:1768} ERROR - Task failed with exception
Traceback (most recent call last):
  File "/home/airflow/.local/lib/python3.8/site-packages/airflow/operators/python.py", line 175, in execute
    return_value = self.execute_callable()
  File "/home/airflow/.local/lib/python3.8/site-packages/airflow/operators/python.py", line 192, in execute_callable
    return self.python_callable(*self.op_args, **self.op_kwargs)
  File "/opt/airflow/plugins/transformers/debts_tracker/debts_tracker_transformer.py", line 69, in validate_payment_data
    debts_objs = debts_data.get("debts")
AttributeError: 'NoneType' object has no attribute 'get'
[2023-01-22T01:44:58.340+0000] {taskinstance.py:1318} INFO - Marking task as UP_FOR_RETRY. dag_id=debts_tracker_etl, task_id=validate_payment_data, execution_date=20230122T014453, start_date=20230122T014458, end_date=20230122T014458
[2023-01-22T01:44:58.350+0000] {standard_task_runner.py:100} ERROR - Failed to execute job 266 for task validate_payment_data ('NoneType' object has no attribute 'get'; 16955)
[2023-01-22T01:44:58.368+0000] {local_task_job.py:208} INFO - Task exited with return code 1
[2023-01-22T01:44:58.385+0000] {taskinstance.py:2578} INFO - 0 downstream tasks scheduled from follow-on schedule check
