[2023-01-21T06:16:36.880+0000] {taskinstance.py:1083} INFO - Dependencies all met for <TaskInstance: crypto_coins_etl.insert_coins manual__2023-01-21T06:16:31.952062+00:00 [queued]>
[2023-01-21T06:16:36.892+0000] {taskinstance.py:1083} INFO - Dependencies all met for <TaskInstance: crypto_coins_etl.insert_coins manual__2023-01-21T06:16:31.952062+00:00 [queued]>
[2023-01-21T06:16:36.893+0000] {taskinstance.py:1279} INFO - 
--------------------------------------------------------------------------------
[2023-01-21T06:16:36.894+0000] {taskinstance.py:1280} INFO - Starting attempt 1 of 1
[2023-01-21T06:16:36.894+0000] {taskinstance.py:1281} INFO - 
--------------------------------------------------------------------------------
[2023-01-21T06:16:36.908+0000] {taskinstance.py:1300} INFO - Executing <Task(PythonOperator): insert_coins> on 2023-01-21 06:16:31.952062+00:00
[2023-01-21T06:16:36.914+0000] {standard_task_runner.py:55} INFO - Started process 3696 to run task
[2023-01-21T06:16:36.919+0000] {standard_task_runner.py:82} INFO - Running: ['***', 'tasks', 'run', 'crypto_coins_etl', 'insert_coins', 'manual__2023-01-21T06:16:31.952062+00:00', '--job-id', '93', '--raw', '--subdir', 'DAGS_FOLDER/crypto_coins_etl.py', '--cfg-path', '/tmp/tmp45sajae3']
[2023-01-21T06:16:36.923+0000] {standard_task_runner.py:83} INFO - Job 93: Subtask insert_coins
[2023-01-21T06:16:37.001+0000] {task_command.py:388} INFO - Running <TaskInstance: crypto_coins_etl.insert_coins manual__2023-01-21T06:16:31.952062+00:00 [running]> on host ac5a85f5e1cc
[2023-01-21T06:16:37.067+0000] {taskinstance.py:1507} INFO - Exporting the following env vars:
AIRFLOW_CTX_DAG_OWNER=***
AIRFLOW_CTX_DAG_ID=crypto_coins_etl
AIRFLOW_CTX_TASK_ID=insert_coins
AIRFLOW_CTX_EXECUTION_DATE=2023-01-21T06:16:31.952062+00:00
AIRFLOW_CTX_TRY_NUMBER=1
AIRFLOW_CTX_DAG_RUN_ID=manual__2023-01-21T06:16:31.952062+00:00
[2023-01-21T06:16:37.097+0000] {coin.py:34} INFO - saving coin Bitcoin...
[2023-01-21T06:16:37.109+0000] {coin.py:47} ERROR - coin could not be store Bitcoin.                             Error (psycopg2.errors.NotNullViolation) null value in column "id" of relation "coin" violates not-null constraint
DETAIL:  Failing row contains (null, Bitcoin, btc, 22583, 22732, 20918).

[SQL: INSERT INTO coin (name, symbol, current_price, high_24h, low_24h) VALUES (%(name)s, %(symbol)s, %(current_price)s, %(high_24h)s, %(low_24h)s) RETURNING coin.id]
[parameters: {'name': 'Bitcoin', 'symbol': 'btc', 'current_price': 22583, 'high_24h': 22732, 'low_24h': 20918}]
(Background on this error at: https://sqlalche.me/e/14/gkpj) .traceback: Traceback (most recent call last):
  File "/home/***/.local/lib/python3.8/site-packages/sqlalchemy/engine/base.py", line 1900, in _execute_context
    self.dialect.do_execute(
  File "/home/***/.local/lib/python3.8/site-packages/sqlalchemy/engine/default.py", line 736, in do_execute
    cursor.execute(statement, parameters)
psycopg2.errors.NotNullViolation: null value in column "id" of relation "coin" violates not-null constraint
DETAIL:  Failing row contains (null, Bitcoin, btc, 22583, 22732, 20918).


The above exception was the direct cause of the following exception:

Traceback (most recent call last):
  File "/opt/***/plugins/models/coin.py", line 45, in create
    db_session.commit()
  File "<string>", line 2, in commit
  File "/home/***/.local/lib/python3.8/site-packages/sqlalchemy/orm/session.py", line 1451, in commit
    self._transaction.commit(_to_root=self.future)
  File "/home/***/.local/lib/python3.8/site-packages/sqlalchemy/orm/session.py", line 829, in commit
    self._prepare_impl()
  File "/home/***/.local/lib/python3.8/site-packages/sqlalchemy/orm/session.py", line 808, in _prepare_impl
    self.session.flush()
  File "/home/***/.local/lib/python3.8/site-packages/sqlalchemy/orm/session.py", line 3444, in flush
    self._flush(objects)
  File "/home/***/.local/lib/python3.8/site-packages/sqlalchemy/orm/session.py", line 3584, in _flush
    transaction.rollback(_capture_exception=True)
  File "/home/***/.local/lib/python3.8/site-packages/sqlalchemy/util/langhelpers.py", line 70, in __exit__
    compat.raise_(
  File "/home/***/.local/lib/python3.8/site-packages/sqlalchemy/util/compat.py", line 211, in raise_
    raise exception
  File "/home/***/.local/lib/python3.8/site-packages/sqlalchemy/orm/session.py", line 3544, in _flush
    flush_context.execute()
  File "/home/***/.local/lib/python3.8/site-packages/sqlalchemy/orm/unitofwork.py", line 456, in execute
    rec.execute(self)
  File "/home/***/.local/lib/python3.8/site-packages/sqlalchemy/orm/unitofwork.py", line 630, in execute
    util.preloaded.orm_persistence.save_obj(
  File "/home/***/.local/lib/python3.8/site-packages/sqlalchemy/orm/persistence.py", line 245, in save_obj
    _emit_insert_statements(
  File "/home/***/.local/lib/python3.8/site-packages/sqlalchemy/orm/persistence.py", line 1238, in _emit_insert_statements
    result = connection._execute_20(
  File "/home/***/.local/lib/python3.8/site-packages/sqlalchemy/engine/base.py", line 1705, in _execute_20
    return meth(self, args_10style, kwargs_10style, execution_options)
  File "/home/***/.local/lib/python3.8/site-packages/sqlalchemy/sql/elements.py", line 334, in _execute_on_connection
    return connection._execute_clauseelement(
  File "/home/***/.local/lib/python3.8/site-packages/sqlalchemy/engine/base.py", line 1572, in _execute_clauseelement
    ret = self._execute_context(
  File "/home/***/.local/lib/python3.8/site-packages/sqlalchemy/engine/base.py", line 1943, in _execute_context
    self._handle_dbapi_exception(
  File "/home/***/.local/lib/python3.8/site-packages/sqlalchemy/engine/base.py", line 2124, in _handle_dbapi_exception
    util.raise_(
  File "/home/***/.local/lib/python3.8/site-packages/sqlalchemy/util/compat.py", line 211, in raise_
    raise exception
  File "/home/***/.local/lib/python3.8/site-packages/sqlalchemy/engine/base.py", line 1900, in _execute_context
    self.dialect.do_execute(
  File "/home/***/.local/lib/python3.8/site-packages/sqlalchemy/engine/default.py", line 736, in do_execute
    cursor.execute(statement, parameters)
sqlalchemy.exc.IntegrityError: (psycopg2.errors.NotNullViolation) null value in column "id" of relation "coin" violates not-null constraint
DETAIL:  Failing row contains (null, Bitcoin, btc, 22583, 22732, 20918).

[SQL: INSERT INTO coin (name, symbol, current_price, high_24h, low_24h) VALUES (%(name)s, %(symbol)s, %(current_price)s, %(high_24h)s, %(low_24h)s) RETURNING coin.id]
[parameters: {'name': 'Bitcoin', 'symbol': 'btc', 'current_price': 22583, 'high_24h': 22732, 'low_24h': 20918}]
(Background on this error at: https://sqlalche.me/e/14/gkpj)

[2023-01-21T06:16:37.111+0000] {taskinstance.py:1768} ERROR - Task failed with exception
Traceback (most recent call last):
  File "/home/airflow/.local/lib/python3.8/site-packages/airflow/operators/python.py", line 175, in execute
    return_value = self.execute_callable()
  File "/home/airflow/.local/lib/python3.8/site-packages/airflow/operators/python.py", line 192, in execute_callable
    return self.python_callable(*self.op_args, **self.op_kwargs)
  File "/opt/airflow/plugins/transformers/crypto/crypto_transformer.py", line 24, in insert_coin_in_db
    Coin.create(coin)
  File "/opt/airflow/plugins/models/coin.py", line 28, in create
    coin_checker = cls.get_coin_by_symbol(coin_info['symbol'])
  File "/opt/airflow/plugins/models/coin.py", line 54, in get_coin_by_symbol
    return cls.query.filter(cls.symbol == symbol).first()
  File "/home/airflow/.local/lib/python3.8/site-packages/sqlalchemy/orm/query.py", line 2824, in first
    return self.limit(1)._iter().first()
  File "/home/airflow/.local/lib/python3.8/site-packages/sqlalchemy/orm/query.py", line 2916, in _iter
    result = self.session.execute(
  File "/home/airflow/.local/lib/python3.8/site-packages/sqlalchemy/orm/session.py", line 1713, in execute
    conn = self._connection_for_bind(bind)
  File "/home/airflow/.local/lib/python3.8/site-packages/sqlalchemy/orm/session.py", line 1552, in _connection_for_bind
    return self._transaction._connection_for_bind(
  File "/home/airflow/.local/lib/python3.8/site-packages/sqlalchemy/orm/session.py", line 721, in _connection_for_bind
    self._assert_active()
  File "/home/airflow/.local/lib/python3.8/site-packages/sqlalchemy/orm/session.py", line 601, in _assert_active
    raise sa_exc.PendingRollbackError(
sqlalchemy.exc.PendingRollbackError: This Session's transaction has been rolled back due to a previous exception during flush. To begin a new transaction with this Session, first issue Session.rollback(). Original exception was: (psycopg2.errors.NotNullViolation) null value in column "id" of relation "coin" violates not-null constraint
DETAIL:  Failing row contains (null, Bitcoin, btc, 22583, 22732, 20918).

[SQL: INSERT INTO coin (name, symbol, current_price, high_24h, low_24h) VALUES (%(name)s, %(symbol)s, %(current_price)s, %(high_24h)s, %(low_24h)s) RETURNING coin.id]
[parameters: {'name': 'Bitcoin', 'symbol': 'btc', 'current_price': 22583, 'high_24h': 22732, 'low_24h': 20918}]
(Background on this error at: https://sqlalche.me/e/14/gkpj) (Background on this error at: https://sqlalche.me/e/14/7s2a)
[2023-01-21T06:16:37.124+0000] {taskinstance.py:1318} INFO - Marking task as FAILED. dag_id=crypto_coins_etl, task_id=insert_coins, execution_date=20230121T061631, start_date=20230121T061636, end_date=20230121T061637
[2023-01-21T06:16:37.155+0000] {standard_task_runner.py:100} ERROR - Failed to execute job 93 for task insert_coins (This Session's transaction has been rolled back due to a previous exception during flush. To begin a new transaction with this Session, first issue Session.rollback(). Original exception was: (psycopg2.errors.NotNullViolation) null value in column "id" of relation "coin" violates not-null constraint
DETAIL:  Failing row contains (null, Bitcoin, btc, 22583, 22732, 20918).

[SQL: INSERT INTO coin (name, symbol, current_price, high_24h, low_24h) VALUES (%(name)s, %(symbol)s, %(current_price)s, %(high_24h)s, %(low_24h)s) RETURNING coin.id]
[parameters: {'name': 'Bitcoin', 'symbol': 'btc', 'current_price': 22583, 'high_24h': 22732, 'low_24h': 20918}]
(Background on this error at: https://sqlalche.me/e/14/gkpj) (Background on this error at: https://sqlalche.me/e/14/7s2a); 3696)
[2023-01-21T06:16:37.173+0000] {local_task_job.py:208} INFO - Task exited with return code 1
[2023-01-21T06:16:37.192+0000] {taskinstance.py:2578} INFO - 0 downstream tasks scheduled from follow-on schedule check
