[2023-01-22T03:49:00.392+0000] {taskinstance.py:1083} INFO - Dependencies all met for <TaskInstance: debts_tracker_etl.create_encrypt_file manual__2023-01-22T03:48:48.649764+00:00 [queued]>
[2023-01-22T03:49:00.404+0000] {taskinstance.py:1083} INFO - Dependencies all met for <TaskInstance: debts_tracker_etl.create_encrypt_file manual__2023-01-22T03:48:48.649764+00:00 [queued]>
[2023-01-22T03:49:00.405+0000] {taskinstance.py:1279} INFO - 
--------------------------------------------------------------------------------
[2023-01-22T03:49:00.406+0000] {taskinstance.py:1280} INFO - Starting attempt 2 of 2
[2023-01-22T03:49:00.407+0000] {taskinstance.py:1281} INFO - 
--------------------------------------------------------------------------------
[2023-01-22T03:49:00.424+0000] {taskinstance.py:1300} INFO - Executing <Task(PythonOperator): create_encrypt_file> on 2023-01-22 03:48:48.649764+00:00
[2023-01-22T03:49:00.431+0000] {standard_task_runner.py:55} INFO - Started process 1705 to run task
[2023-01-22T03:49:00.436+0000] {standard_task_runner.py:82} INFO - Running: ['***', 'tasks', 'run', 'debts_tracker_etl', 'create_encrypt_file', 'manual__2023-01-22T03:48:48.649764+00:00', '--job-id', '37', '--raw', '--subdir', 'DAGS_FOLDER/debts_tracker_etl.py', '--cfg-path', '/tmp/tmp_dgnt1ln']
[2023-01-22T03:49:00.440+0000] {standard_task_runner.py:83} INFO - Job 37: Subtask create_encrypt_file
[2023-01-22T03:49:00.525+0000] {task_command.py:388} INFO - Running <TaskInstance: debts_tracker_etl.create_encrypt_file manual__2023-01-22T03:48:48.649764+00:00 [running]> on host 4b1c480b6ccb
[2023-01-22T03:49:00.599+0000] {taskinstance.py:1507} INFO - Exporting the following env vars:
AIRFLOW_CTX_DAG_OWNER=Tony Stark, Peter Parker
AIRFLOW_CTX_DAG_ID=debts_tracker_etl
AIRFLOW_CTX_TASK_ID=create_encrypt_file
AIRFLOW_CTX_EXECUTION_DATE=2023-01-22T03:48:48.649764+00:00
AIRFLOW_CTX_TRY_NUMBER=2
AIRFLOW_CTX_DAG_RUN_ID=manual__2023-01-22T03:48:48.649764+00:00
[2023-01-22T03:49:00.601+0000] {taskinstance.py:1768} ERROR - Task failed with exception
Traceback (most recent call last):
  File "/home/airflow/.local/lib/python3.8/site-packages/airflow/operators/python.py", line 175, in execute
    return_value = self.execute_callable()
  File "/home/airflow/.local/lib/python3.8/site-packages/airflow/operators/python.py", line 192, in execute_callable
    return self.python_callable(*self.op_args, **self.op_kwargs)
TypeError: encrypt_debts_data() missing 1 required positional argument: 'op_kwargs'
[2023-01-22T03:49:00.610+0000] {taskinstance.py:1318} INFO - Marking task as FAILED. dag_id=debts_tracker_etl, task_id=create_encrypt_file, execution_date=20230122T034848, start_date=20230122T034900, end_date=20230122T034900
[2023-01-22T03:49:00.622+0000] {standard_task_runner.py:100} ERROR - Failed to execute job 37 for task create_encrypt_file (encrypt_debts_data() missing 1 required positional argument: 'op_kwargs'; 1705)
[2023-01-22T03:49:00.649+0000] {local_task_job.py:208} INFO - Task exited with return code 1
[2023-01-22T03:49:00.673+0000] {taskinstance.py:2578} INFO - 0 downstream tasks scheduled from follow-on schedule check
