[2023-01-22T02:29:47.271+0000] {taskinstance.py:1083} INFO - Dependencies all met for <TaskInstance: debts_tracker_etl.create_encrypt_file manual__2023-01-22T02:29:35.931653+00:00 [queued]>
[2023-01-22T02:29:47.283+0000] {taskinstance.py:1083} INFO - Dependencies all met for <TaskInstance: debts_tracker_etl.create_encrypt_file manual__2023-01-22T02:29:35.931653+00:00 [queued]>
[2023-01-22T02:29:47.284+0000] {taskinstance.py:1279} INFO - 
--------------------------------------------------------------------------------
[2023-01-22T02:29:47.284+0000] {taskinstance.py:1280} INFO - Starting attempt 2 of 2
[2023-01-22T02:29:47.285+0000] {taskinstance.py:1281} INFO - 
--------------------------------------------------------------------------------
[2023-01-22T02:29:47.298+0000] {taskinstance.py:1300} INFO - Executing <Task(PythonOperator): create_encrypt_file> on 2023-01-22 02:29:35.931653+00:00
[2023-01-22T02:29:47.304+0000] {standard_task_runner.py:55} INFO - Started process 19884 to run task
[2023-01-22T02:29:47.309+0000] {standard_task_runner.py:82} INFO - Running: ['***', 'tasks', 'run', 'debts_tracker_etl', 'create_encrypt_file', 'manual__2023-01-22T02:29:35.931653+00:00', '--job-id', '306', '--raw', '--subdir', 'DAGS_FOLDER/debts_tracker_etl.py', '--cfg-path', '/tmp/tmpweydy8e3']
[2023-01-22T02:29:47.313+0000] {standard_task_runner.py:83} INFO - Job 306: Subtask create_encrypt_file
[2023-01-22T02:29:47.393+0000] {task_command.py:388} INFO - Running <TaskInstance: debts_tracker_etl.create_encrypt_file manual__2023-01-22T02:29:35.931653+00:00 [running]> on host 365d47c8e5b5
[2023-01-22T02:29:47.461+0000] {taskinstance.py:1507} INFO - Exporting the following env vars:
AIRFLOW_CTX_DAG_OWNER=Tony Stark, Peter Parker
AIRFLOW_CTX_DAG_ID=debts_tracker_etl
AIRFLOW_CTX_TASK_ID=create_encrypt_file
AIRFLOW_CTX_EXECUTION_DATE=2023-01-22T02:29:35.931653+00:00
AIRFLOW_CTX_TRY_NUMBER=2
AIRFLOW_CTX_DAG_RUN_ID=manual__2023-01-22T02:29:35.931653+00:00
[2023-01-22T02:29:47.481+0000] {taskinstance.py:1768} ERROR - Task failed with exception
Traceback (most recent call last):
  File "/home/airflow/.local/lib/python3.8/site-packages/airflow/operators/python.py", line 175, in execute
    return_value = self.execute_callable()
  File "/home/airflow/.local/lib/python3.8/site-packages/airflow/operators/python.py", line 192, in execute_callable
    return self.python_callable(*self.op_args, **self.op_kwargs)
  File "/opt/airflow/plugins/transformers/debts_tracker/debts_tracker_transformer.py", line 117, in encrypt_debts_data
    with open('/store_files_airflow/clean_store_transactions.csv', 'wb') as encrypted_file:
FileNotFoundError: [Errno 2] No such file or directory: '/store_files_airflow/clean_store_transactions.csv'
[2023-01-22T02:29:47.492+0000] {taskinstance.py:1318} INFO - Marking task as FAILED. dag_id=debts_tracker_etl, task_id=create_encrypt_file, execution_date=20230122T022935, start_date=20230122T022947, end_date=20230122T022947
[2023-01-22T02:29:47.504+0000] {standard_task_runner.py:100} ERROR - Failed to execute job 306 for task create_encrypt_file ([Errno 2] No such file or directory: '/store_files_airflow/clean_store_transactions.csv'; 19884)
[2023-01-22T02:29:47.522+0000] {local_task_job.py:208} INFO - Task exited with return code 1
[2023-01-22T02:29:47.542+0000] {taskinstance.py:2578} INFO - 0 downstream tasks scheduled from follow-on schedule check
