[2023-01-22T02:29:41.109+0000] {taskinstance.py:1083} INFO - Dependencies all met for <TaskInstance: debts_tracker_etl.create_encrypt_file manual__2023-01-22T02:29:35.931653+00:00 [queued]>
[2023-01-22T02:29:41.120+0000] {taskinstance.py:1083} INFO - Dependencies all met for <TaskInstance: debts_tracker_etl.create_encrypt_file manual__2023-01-22T02:29:35.931653+00:00 [queued]>
[2023-01-22T02:29:41.121+0000] {taskinstance.py:1279} INFO - 
--------------------------------------------------------------------------------
[2023-01-22T02:29:41.122+0000] {taskinstance.py:1280} INFO - Starting attempt 1 of 2
[2023-01-22T02:29:41.123+0000] {taskinstance.py:1281} INFO - 
--------------------------------------------------------------------------------
[2023-01-22T02:29:41.135+0000] {taskinstance.py:1300} INFO - Executing <Task(PythonOperator): create_encrypt_file> on 2023-01-22 02:29:35.931653+00:00
[2023-01-22T02:29:41.141+0000] {standard_task_runner.py:55} INFO - Started process 19873 to run task
[2023-01-22T02:29:41.145+0000] {standard_task_runner.py:82} INFO - Running: ['***', 'tasks', 'run', 'debts_tracker_etl', 'create_encrypt_file', 'manual__2023-01-22T02:29:35.931653+00:00', '--job-id', '305', '--raw', '--subdir', 'DAGS_FOLDER/debts_tracker_etl.py', '--cfg-path', '/tmp/tmpizr4iuxk']
[2023-01-22T02:29:41.149+0000] {standard_task_runner.py:83} INFO - Job 305: Subtask create_encrypt_file
[2023-01-22T02:29:41.230+0000] {task_command.py:388} INFO - Running <TaskInstance: debts_tracker_etl.create_encrypt_file manual__2023-01-22T02:29:35.931653+00:00 [running]> on host 365d47c8e5b5
[2023-01-22T02:29:41.302+0000] {taskinstance.py:1507} INFO - Exporting the following env vars:
AIRFLOW_CTX_DAG_OWNER=Tony Stark, Peter Parker
AIRFLOW_CTX_DAG_ID=debts_tracker_etl
AIRFLOW_CTX_TASK_ID=create_encrypt_file
AIRFLOW_CTX_EXECUTION_DATE=2023-01-22T02:29:35.931653+00:00
AIRFLOW_CTX_TRY_NUMBER=1
AIRFLOW_CTX_DAG_RUN_ID=manual__2023-01-22T02:29:35.931653+00:00
[2023-01-22T02:29:41.337+0000] {taskinstance.py:1768} ERROR - Task failed with exception
Traceback (most recent call last):
  File "/home/airflow/.local/lib/python3.8/site-packages/airflow/operators/python.py", line 175, in execute
    return_value = self.execute_callable()
  File "/home/airflow/.local/lib/python3.8/site-packages/airflow/operators/python.py", line 192, in execute_callable
    return self.python_callable(*self.op_args, **self.op_kwargs)
  File "/opt/airflow/plugins/transformers/debts_tracker/debts_tracker_transformer.py", line 117, in encrypt_debts_data
    with open('/store_files_airflow/clean_store_transactions.csv', 'wb') as encrypted_file:
FileNotFoundError: [Errno 2] No such file or directory: '/store_files_airflow/clean_store_transactions.csv'
[2023-01-22T02:29:41.347+0000] {taskinstance.py:1318} INFO - Marking task as UP_FOR_RETRY. dag_id=debts_tracker_etl, task_id=create_encrypt_file, execution_date=20230122T022935, start_date=20230122T022941, end_date=20230122T022941
[2023-01-22T02:29:41.359+0000] {standard_task_runner.py:100} ERROR - Failed to execute job 305 for task create_encrypt_file ([Errno 2] No such file or directory: '/store_files_airflow/clean_store_transactions.csv'; 19873)
[2023-01-22T02:29:41.399+0000] {local_task_job.py:208} INFO - Task exited with return code 1
[2023-01-22T02:29:41.422+0000] {taskinstance.py:2578} INFO - 0 downstream tasks scheduled from follow-on schedule check
